<?xml version="1.0"?>
<robot name = "my_diff_drive_robot_essentials" xmlns:xacro="fttp://ros.org/wiki/xacro">

    <xacro:macro name = "robot_wheel" params="prefix">
        <link name="${prefix}_robot_wheel">
            <visual>
                <origin
                xyz="0 0 0"
                rpy="1.57 0 0" />
                <geometry>
                    <cylinder length=".05" radius=".1" />
                </geometry>
            </visual>
            <collision>
                <origin
                xyz="0 0 0"
                rpy="1.57 0 0" />
                <geometry>
                    <cylinder length=".05" radius=".1" />
                </geometry>
            </collision>
            <inertial>
                <mass value = "0.2" />
                <origin xyz="0 0 0" rpy ="1.57 0 0" />
                <inertia ixx="0.0005416666667" ixy="0" ixz="0" iyy="0.0005416666667" iyz="0" izz="0.001" />
                <!-- fixed inertial value according to values and correct formula -->
            </inertial>
        </link>
    </xacro:macro>

    <xacro:macro name="wheel_joint" params="prefix origin">
        <joint name="${prefix}_wheel_joint" type="continuous">
            <axis xyz="0 1 0" />
            <parent link = "robot_chassis" />
            <child link = "${prefix}_robot_wheel" />
            <origin xyz="${origin}" rpy="0 0 0" />
            <limit effort="10000" velocity="1000"/>
            <joint_properties damping="1.0" friction="1.0"/>
        </joint>
    </xacro:macro>
    
</robot>